Workbook

Sheet 혈맹원 정보
A1: 닉네임 | B1: 직책 | C1: 클래스 | D1: 속성 | E1: 디코고유id | F1: 연락처 | G1: 특이사항 | K1: 닉네임 | L1: 직책 | M1: 클래스 | N1: 속성 | O1: 연락처 | P1: 특이사황ㄹ
A2: 개백수 | B2: 혈맹원 | C2: 기사 | D2: 속성X | E2: 1053683139056255027 | I2: =ISTEXT(E2) -> TRUE | K2: 개백수 | L2: 혈맹원 | M2: 기사 | N2: 속성X
A3: 김현지 | B3: 혈맹원 | C3: 마법사 | E3: 1482308176677437453 | I3: =ISTEXT(E3) -> TRUE
A4: 꽃냥 | B4: 혈맹원 | C4: 기사 | E4: 1346882990118273115 | I4: =ISTEXT(E4) -> TRUE | K4: 김현지 | L4: 혈맹원 | M4: 마법사
A5: 다뢰 | B5: 혈맹원 | C5: 요정 | D5: 땅 | E5: 376298390822060034 | I5: =ISTEXT(E5) -> TRUE | K5: 꼬치 | L5: 혈맹원 | M5: 요정
A6: 닥스 | B6: 혈맹원 | C6: 요정 | D6: 땅 | E6: 312126990935130124 | I6: =ISTEXT(E6) -> TRUE | K6: 꽃냥 | L6: 혈맹원 | M6: 기사
A7: 당구장 | B7: 혈맹원 | C7: 요정 | E7: 1262879302110937170 | I7: =ISTEXT(E7) -> TRUE
A8: 대곡주 | B8: 혈맹원 | C8: 요정 | E8: 1331168014845874209 | I8: =ISTEXT(E8) -> TRUE | K8: 다뢰 | L8: 혈맹원 | M8: 요정 | N8: 땅
A9: 덱스 | B9: 혈맹원 | C9: 기사 | E9: 569894354504777749 | I9: =ISTEXT(E9) -> TRUE | K9: 닥스 | L9: 혈맹원 | M9: 요정 | N9: 땅
A10: 두끗 | B10: 혈맹원 | C10: 요정 | E10: 388675531538956289 | I10: =ISTEXT(E10) -> TRUE | K10: 대곡주 | L10: 혈맹원 | M10: 요정
A11: 두둥탁 | B11: 혈맹원 | C11: 마법사 | D11: 속성X | E11: 790465405164453908 | I11: =ISTEXT(E11) -> TRUE | K11: 대방이 | L11: 혈맹원 | M11: 요정
A12: 드레이크 | B12: 혈맹원 | C12: 기사 | D12: 속성X | E12: 711844803767435315 | I12: =ISTEXT(E12) -> TRUE | K12: 대위덕명왕 | L12: 혈맹원 | M12: 기사 | N12: 속성X | O12: 010-9183-9630
A13: 드레이크1 | B13: 혈맹원 | C13: 기사 | E13: 382752304962469890 | I13: =ISTEXT(E13) -> TRUE | K13: 덱스 | L13: 혈맹원 | M13: 기사
A14: 또가스 | B14: 혈맹원 | C14: 요정 | E14: 426032303555477505 | I14: =ISTEXT(E14) -> TRUE | K14: 두둥탁 | L14: 혈맹원 | M14: 마법사 | N14: 속성X
A15: 레오나르도 | B15: 혈맹원 | C15: 요정 | E15: 330757131504582658 | I15: =ISTEXT(E15) -> TRUE | K15: 드레이크 | L15: 혈맹원 | M15: 기사 | N15: 속성X
A16: 민창 | B16: 혈맹원 | C16: 요정 | E16: 561208372171505683 | I16: =ISTEXT(E16) -> TRUE | K16: 드레이크1 | L16: 혈맹원 | M16: 기사
A17: 밀떡 | B17: 혈맹원 | C17: 요정 | E17: 1483830618507841587 | I17: =ISTEXT(E17) -> TRUE | K17: 레오나르도 | L17: 혈맹원 | M17: 요정
A18: 뱀 | B18: 혈맹원 | C18: 마법사 | E18: 442636969193766924 | I18: =ISTEXT(E18) -> TRUE | K18: 민창 | L18: 혈맹원 | M18: 요정
A19: 복식 | B19: 혈맹원 | C19: 요정 | D19: 바람 | E19: 1108135082461511814 | I19: =ISTEXT(E19) -> TRUE | K19: 밀끄 | L19: 혈맹원 | M19: 요정
A20: 비에고 | B20: 혈맹원 | C20: 기사 | D20: 속성X | E20: 939455236739837982 | I20: =ISTEXT(E20) -> TRUE | K20: 밀떡 | L20: 혈맹원 | M20: 요정
A21: 새롬 | B21: 혈맹원 | C21: 요정 | E21: 914856849310900234 | I21: =ISTEXT(E21) -> TRUE | K21: 버프의신 | L21: 혈맹원
A22: 세끗 | B22: 혈맹원 | C22: 요정 | E22: 1490259813962350592 | I22: =ISTEXT(E22) -> TRUE | K22: 복식 | L22: 혈맹원 | M22: 요정 | N22: 바람
A23: 세이버 | B23: 혈맹원 | C23: 요정 | E23: 1278304254955884730 | I23: =ISTEXT(E23) -> TRUE | K23: 복쫄 | L23: 혈맹원 | M23: 마법사 | N23: 속성X
A24: 스타 | B24: 혈맹원 | C24: 마법사 | D24: 속성X | E24: 397696170346151946 | I24: =ISTEXT(E24) -> TRUE | K24: 비에고 | L24: 혈맹원 | M24: 기사 | N24: 속성X
A25: 스타1 | B25: 혈맹원 | C25: 마법사 | E25: 612606740541997066 | G25: 스타부주1 | I25: =ISTEXT(E25) -> TRUE | K25: 비에고1 | L25: 혈맹원 | M25: 요정
A26: 스팸라이트 | B26: 혈맹원 | C26: 요정 | E26: 1489588682376613888 | I26: =ISTEXT(E26) -> TRUE | K26: 뽀둥뽀둥 | L26: 혈맹원
A27: 시드랏슈 | B27: 부군주 | C27: 마법사 | D27: 속성X | E27: 583263839856885770 | I27: =ISTEXT(E27) -> TRUE | K27: 세이버 | L27: 혈맹원 | M27: 요정
A28: 시진핑 | B28: 혈맹원 | C28: 마법사 | E28: 1343575157842640957 | I28: =ISTEXT(E28) -> TRUE | K28: 스타 | L28: 혈맹원 | M28: 마법사 | N28: 속성X
A29: 신문 | B29: 혈맹원 | C29: 요정 | E29: 661750424591663134 | I29: =ISTEXT(E29) -> TRUE | K29: 스팸라이트 | L29: 혈맹원 | M29: 요정
A30: 쌀떡 | B30: 혈맹원 | C30: 요정 | E30: 1487057737832464544 | I30: =ISTEXT(E30) -> TRUE | K30: 시드랏슈 | L30: 부군주 | M30: 마법사 | N30: 속성X
A31: 쌀떡 | B31: 혈맹원 | C31: 요정 | E31: 1487057737832464544 | I31: =ISTEXT(E31) -> TRUE | K31: 시진핑 | L31: 혈맹원 | M31: 마법사
A32: 썽이 | B32: 혈맹원 | C32: 요정 | E32: 576257871612870656 | G32: 드레이크 썽이 | I32: =ISTEXT(E32) -> TRUE | K32: 신문 | L32: 혈맹원 | M32: 요정
A33: 쑥떡 | B33: 혈맹원 | C33: 요정 | E33: 373116772166926337 | I33: =ISTEXT(E33) -> TRUE | K33: 쌀떡 | L33: 혈맹원 | M33: 요정
A34: 아스테어 | B34: 혈맹원 | C34: 기사 | D34: 속성X | E34: 538344294579437598 | I34: =ISTEXT(E34) -> TRUE | K34: 쑥떡 | L34: 혈맹원 | M34: 요정
A35: 악당 | B35: 혈맹원 | C35: 요정 | E35: 366506563957030913 | I35: =ISTEXT(E35) -> TRUE | K35: 아스테어 | L35: 혈맹원 | M35: 기사 | N35: 속성X
A36: 악당1 | B36: 혈맹원 | C36: 요정 | E36: 366506563957030913 | G36: 악당 부주 조커 | I36: =ISTEXT(E36) -> TRUE | K36: 악당 | L36: 혈맹원 | M36: 요정
A37: 어쩐지 | B37: 혈맹원 | C37: 마법사 | E37: 721281407288213544 | I37: =ISTEXT(E37) -> TRUE | K37: 악풍 | L37: 혈맹원 | M37: 요정
A38: 얼음여왕 | B38: 혈맹원 | C38: 요정 | E38: 865842387347046440 | I38: =ISTEXT(E38) -> TRUE | K38: 안선호 | L38: 혈맹원 | M38: 기사 | N38: 속성X
A39: 에바 | B39: 혈맹원 | C39: 마법사 | D39: 속성X | E39: 1353407800679596115 | I39: =ISTEXT(E39) -> TRUE | K39: 어쩐지 | L39: 혈맹원 | M39: 마법사
A40: 역도 | B40: 혈맹원 | C40: 기사 | E40: 346930383591571457 | I40: =ISTEXT(E40) -> TRUE | K40: 에바 | L40: 혈맹원 | M40: 마법사 | N40: 속성X
...

Sheet 보탐 참여율
A1: =IFERROR(__xludf.DUMMYFUNCTION("FILTER('혈맹원 정보'!A2:A1000, '혈맹원 정보'!A2:A1000<>"""")"),"개백수") -> 개백수 | B1: FALSE | C1: =IF(Z1="","",COUNTIF('건들지말것'!A:A,Z1)) -> 126 | D1: =C1/$H$1 -> 0.35492958 | E1: =IFERROR(VLOOKUP(TRIM(A1), '혈맹원 정보'!A:C, 3, FALSE), "") -> 기사 | F1: FALSE | G1: FALSE | H1: 355 | X1: =ISTEXT(Z1) -> TRUE | Z1: {=IF(A1="","", IFERROR( INDEX('혈맹원 정보'!E$2:E1000, MATCH(A1, '혈맹원 정보'!A$2:A1000, 0) ), ""))} -> 1053683139056255027
A2: =IFERROR(__xludf.DUMMYFUNCTION("""COMPUTED_VALUE"""),"김현지") -> 김현지 | B2: FALSE | C2: =IF(Z2="","",COUNTIF('건들지말것'!A:A,Z2)) -> 79 | D2: =C2/$H$1 -> 0.22253521 | E2: =IFERROR(VLOOKUP(TRIM(A2), '혈맹원 정보'!A:C, 3, FALSE), "") -> 마법사 | F2: FALSE | G2: 26.05.04.19시 | I2: 26.5.4일19시부터 보탐 자동체크 | X2: =ISTEXT(Z2) -> TRUE | Z2: {=IF(A2="","", IFERROR( INDEX('혈맹원 정보'!E$2:E1000, MATCH(A2, '혈맹원 정보'!A$2:A1000, 0) ), ""))} -> 1482308176677437453
A3: =IFERROR(__xludf.DUMMYFUNCTION("""COMPUTED_VALUE"""),"꽃냥") -> 꽃냥 | B3: FALSE | C3: =IF(Z3="","",COUNTIF('건들지말것'!A:A,Z3)) -> 34 | D3: =C3/$H$1 -> 0.095774648 | E3: =IFERROR(VLOOKUP(TRIM(A3), '혈맹원 정보'!A:C, 3, FALSE), "") -> 기사 | F3: FALSE | X3: =ISTEXT(Z3) -> TRUE | Z3: {=IF(A3="","", IFERROR( INDEX('혈맹원 정보'!E$2:E1000, MATCH(A3, '혈맹원 정보'!A$2:A1000, 0) ), ""))} -> 1346882990118273115
A4: =IFERROR(__xludf.DUMMYFUNCTION("""COMPUTED_VALUE"""),"다뢰") -> 다뢰 | B4: FALSE | C4: =IF(Z4="","",COUNTIF('건들지말것'!A:A,Z4)) -> 26 | D4: =C4/$H$1 -> 0.073239437 | E4: =IFERROR(VLOOKUP(TRIM(A4), '혈맹원 정보'!A:C, 3, FALSE), "") -> 요정 | F4: FALSE | X4: =ISTEXT(Z4) -> TRUE | Z4: {=IF(A4="","", IFERROR( INDEX('혈맹원 정보'!E$2:E1000, MATCH(A4, '혈맹원 정보'!A$2:A1000, 0) ), ""))} -> 376298390822060034
A5: =IFERROR(__xludf.DUMMYFUNCTION("""COMPUTED_VALUE"""),"닥스") -> 닥스 | B5: FALSE | C5: =IF(Z5="","",COUNTIF('건들지말것'!A:A,Z5)) -> 76 | D5: =C5/$H$1 -> 0.21408451 | E5: =IFERROR(VLOOKUP(TRIM(A5), '혈맹원 정보'!A:C, 3, FALSE), "") -> 요정 | F5: FALSE | X5: =ISTEXT(Z5) -> TRUE | Z5: {=IF(A5="","", IFERROR( INDEX('혈맹원 정보'!E$2:E1000, MATCH(A5, '혈맹원 정보'!A$2:A1000, 0) ), ""))} -> 312126990935130124
A6: =IFERROR(__xludf.DUMMYFUNCTION("""COMPUTED_VALUE"""),"당구장") -> 당구장 | B6: FALSE | C6: =IF(Z6="","",COUNTIF('건들지말것'!A:A,Z6)) -> 59 | D6: =C6/$H$1 -> 0.16619718 | E6: =IFERROR(VLOOKUP(TRIM(A6), '혈맹원 정보'!A:C, 3, FALSE), "") -> 요정 | F6: FALSE | G6: 월별 보탐참여율 기록 | X6: =ISTEXT(Z6) -> TRUE | Z6: {=IF(A6="","", IFERROR( INDEX('혈맹원 정보'!E$2:E1000, MATCH(A6, '혈맹원 정보'!A$2:A1000, 0) ), ""))} -> 1262879302110937170
A7: =IFERROR(__xludf.DUMMYFUNCTION("""COMPUTED_VALUE"""),"대곡주") -> 대곡주 | B7: FALSE | C7: =IF(Z7="","",COUNTIF('건들지말것'!A:A,Z7)) -> 158 | D7: =C7/$H$1 -> 0.44507042 | E7: =IFERROR(VLOOKUP(TRIM(A7), '혈맹원 정보'!A:C, 3, FALSE), "") -> 요정 | F7: FALSE | X7: =ISTEXT(Z7) -> TRUE | Z7: {=IF(A7="","", IFERROR( INDEX('혈맹원 정보'!E$2:E1000, MATCH(A7, '혈맹원 정보'!A$2:A1000, 0) ), ""))} -> 1331168014845874209
A8: =IFERROR(__xludf.DUMMYFUNCTION("""COMPUTED_VALUE"""),"덱스") -> 덱스 | B8: FALSE | C8: =IF(Z8="","",COUNTIF('건들지말것'!A:A,Z8)) -> 38 | D8: =C8/$H$1 -> 0.10704225 | E8: =IFERROR(VLOOKUP(TRIM(A8), '혈맹원 정보'!A:C, 3, FALSE), "") -> 기사 | F8: FALSE | G8: FALSE | X8: =ISTEXT(Z8) -> TRUE | Z8: {=IF(A8="","", IFERROR( INDEX('혈맹원 정보'!E$2:E1000, MATCH(A8, '혈맹원 정보'!A$2:A1000, 0) ), ""))} -> 569894354504777749
A9: =IFERROR(__xludf.DUMMYFUNCTION("""COMPUTED_VALUE"""),"두끗") -> 두끗 | B9: FALSE | C9: =IF(Z9="","",COUNTIF('건들지말것'!A:A,Z9)) -> 100 | D9: =C9/$H$1 -> 0.28169014 | E9: =IFERROR(VLOOKUP(TRIM(A9), '혈맹원 정보'!A:C, 3, FALSE), "") -> 요정 | F9: FALSE | X9: =ISTEXT(Z9) -> TRUE | Z9: {=IF(A9="","", IFERROR( INDEX('혈맹원 정보'!E$2:E1000, MATCH(A9, '혈맹원 정보'!A$2:A1000, 0) ), ""))} -> 388675531538956289
A10: =IFERROR(__xludf.DUMMYFUNCTION("""COMPUTED_VALUE"""),"두둥탁") -> 두둥탁 | B10: FALSE | C10: =IF(Z10="","",COUNTIF('건들지말것'!A:A,Z10)) -> 53 | D10: =C10/$H$1 -> 0.14929577 | E10: =IFERROR(VLOOKUP(TRIM(A10), '혈맹원 정보'!A:C, 3, FALSE), "") -> 마법사 | F10: FALSE | G10: FALSE | X10: =ISTEXT(Z10) -> TRUE | Z10: {=IF(A10="","", IFERROR( INDEX('혈맹원 정보'!E$2:E1000, MATCH(A10, '혈맹원 정보'!A$2:A1000, 0) ), ""))} -> 790465405164453908
A11: =IFERROR(__xludf.DUMMYFUNCTION("""COMPUTED_VALUE"""),"드레이크") -> 드레이크 | B11: FALSE | C11: =IF(Z11="","",COUNTIF('건들지말것'!A:A,Z11)) -> 14 | D11: =C11/$H$1 -> 0.03943662 | E11: =IFERROR(VLOOKUP(TRIM(A11), '혈맹원 정보'!A:C, 3, FALSE), "") -> 기사 | F11: FALSE | X11: =ISTEXT(Z11) -> TRUE | Z11: {=IF(A11="","", IFERROR( INDEX('혈맹원 정보'!E$2:E1000, MATCH(A11, '혈맹원 정보'!A$2:A1000, 0) ), ""))} -> 711844803767435315
A12: =IFERROR(__xludf.DUMMYFUNCTION("""COMPUTED_VALUE"""),"드레이크1") -> 드레이크1 | B12: FALSE | C12: =IF(Z12="","",COUNTIF('건들지말것'!A:A,Z12)) -> 110 | D12: =C12/$H$1 -> 0.30985915 | E12: =IFERROR(VLOOKUP(TRIM(A12), '혈맹원 정보'!A:C, 3, FALSE), "") -> 기사 | F12: FALSE | X12: =ISTEXT(Z12) -> TRUE | Z12: {=IF(A12="","", IFERROR( INDEX('혈맹원 정보'!E$2:E1000, MATCH(A12, '혈맹원 정보'!A$2:A1000, 0) ), ""))} -> 382752304962469890
A13: =IFERROR(__xludf.DUMMYFUNCTION("""COMPUTED_VALUE"""),"또가스") -> 또가스 | B13: FALSE | C13: =IF(Z13="","",COUNTIF('건들지말것'!A:A,Z13)) -> 58 | D13: =C13/$H$1 -> 0.16338028 | E13: =IFERROR(VLOOKUP(TRIM(A13), '혈맹원 정보'!A:C, 3, FALSE), "") -> 요정 | F13: FALSE | X13: =ISTEXT(Z13) -> TRUE | Z13: {=IF(A13="","", IFERROR( INDEX('혈맹원 정보'!E$2:E1000, MATCH(A13, '혈맹원 정보'!A$2:A1000, 0) ), ""))} -> 426032303555477505
A14: =IFERROR(__xludf.DUMMYFUNCTION("""COMPUTED_VALUE"""),"레오나르도") -> 레오나르도 | B14: FALSE | C14: =IF(Z14="","",COUNTIF('건들지말것'!A:A,Z14)) -> 118 | D14: =C14/$H$1 -> 0.33239437 | E14: =IFERROR(VLOOKUP(TRIM(A14), '혈맹원 정보'!A:C, 3, FALSE), "") -> 요정 | F14: FALSE | X14: =ISTEXT(Z14) -> TRUE | Z14: {=IF(A14="","", IFERROR( INDEX('혈맹원 정보'!E$2:E1000, MATCH(A14, '혈맹원 정보'!A$2:A1000, 0) ), ""))} -> 330757131504582658
A15: =IFERROR(__xludf.DUMMYFUNCTION("""COMPUTED_VALUE"""),"민창") -> 민창 | B15: FALSE | C15: =IF(Z15="","",COUNTIF('건들지말것'!A:A,Z15)) -> 80 | D15: =C15/$H$1 -> 0.22535211 | E15: =IFERROR(VLOOKUP(TRIM(A15), '혈맹원 정보'!A:C, 3, FALSE), "") -> 요정 | F15: FALSE | X15: =ISTEXT(Z15) -> TRUE | Z15: {=IF(A15="","", IFERROR( INDEX('혈맹원 정보'!E$2:E1000, MATCH(A15, '혈맹원 정보'!A$2:A1000, 0) ), ""))} -> 561208372171505683
A16: =IFERROR(__xludf.DUMMYFUNCTION("""COMPUTED_VALUE"""),"밀떡") -> 밀떡 | B16: FALSE | C16: =IF(Z16="","",COUNTIF('건들지말것'!A:A,Z16)) -> 98 | D16: =C16/$H$1 -> 0.27605634 | E16: =IFERROR(VLOOKUP(TRIM(A16), '혈맹원 정보'!A:C, 3, FALSE), "") -> 요정 | F16: FALSE | X16: =ISTEXT(Z16) -> TRUE | Z16: {=IF(A16="","", IFERROR( INDEX('혈맹원 정보'!E$2:E1000, MATCH(A16, '혈맹원 정보'!A$2:A1000, 0) ), ""))} -> 1483830618507841587
A17: =IFERROR(__xludf.DUMMYFUNCTION("""COMPUTED_VALUE"""),"뱀") -> 뱀 | B17: FALSE | C17: =IF(Z17="","",COUNTIF('건들지말것'!A:A,Z17)) -> 17 | D17: =C17/$H$1 -> 0.047887324 | E17: =IFERROR(VLOOKUP(TRIM(A17), '혈맹원 정보'!A:C, 3, FALSE), "") -> 마법사 | F17: FALSE | X17: =ISTEXT(Z17) -> TRUE | Z17: {=IF(A17="","", IFERROR( INDEX('혈맹원 정보'!E$2:E1000, MATCH(A17, '혈맹원 정보'!A$2:A1000, 0) ), ""))} -> 442636969193766924
A18: =IFERROR(__xludf.DUMMYFUNCTION("""COMPUTED_VALUE"""),"복식") -> 복식 | B18: FALSE | C18: =IF(Z18="","",COUNTIF('건들지말것'!A:A,Z18)) -> 1 | D18: =C18/$H$1 -> 0.0028169014 | E18: =IFERROR(VLOOKUP(TRIM(A18), '혈맹원 정보'!A:C, 3, FALSE), "") -> 요정 | F18: FALSE | X18: =ISTEXT(Z18) -> TRUE | Z18: {=IF(A18="","", IFERROR( INDEX('혈맹원 정보'!E$2:E1000, MATCH(A18, '혈맹원 정보'!A$2:A1000, 0) ), ""))} -> 1108135082461511814
A19: =IFERROR(__xludf.DUMMYFUNCTION("""COMPUTED_VALUE"""),"비에고") -> 비에고 | B19: FALSE | C19: =IF(Z19="","",COUNTIF('건들지말것'!A:A,Z19)) -> 42 | D19: =C19/$H$1 -> 0.11830986 | E19: =IFERROR(VLOOKUP(TRIM(A19), '혈맹원 정보'!A:C, 3, FALSE), "") -> 기사 | F19: FALSE | X19: =ISTEXT(Z19) -> TRUE | Z19: {=IF(A19="","", IFERROR( INDEX('혈맹원 정보'!E$2:E1000, MATCH(A19, '혈맹원 정보'!A$2:A1000, 0) ), ""))} -> 939455236739837982
A20: =IFERROR(__xludf.DUMMYFUNCTION("""COMPUTED_VALUE"""),"새롬") -> 새롬 | B20: FALSE | C20: =IF(Z20="","",COUNTIF('건들지말것'!A:A,Z20)) -> 26 | D20: =C20/$H$1 -> 0.073239437 | E20: =IFERROR(VLOOKUP(TRIM(A20), '혈맹원 정보'!A:C, 3, FALSE), "") -> 요정 | F20: FALSE | X20: =ISTEXT(Z20) -> TRUE | Z20: {=IF(A20="","", IFERROR( INDEX('혈맹원 정보'!E$2:E1000, MATCH(A20, '혈맹원 정보'!A$2:A1000, 0) ), ""))} -> 914856849310900234
A21: =IFERROR(__xludf.DUMMYFUNCTION("""COMPUTED_VALUE"""),"세끗") -> 세끗 | B21: FALSE | C21: =IF(Z21="","",COUNTIF('건들지말것'!A:A,Z21)) -> 83 | D21: =C21/$H$1 -> 0.23380282 | E21: =IFERROR(VLOOKUP(TRIM(A21), '혈맹원 정보'!A:C, 3, FALSE), "") -> 요정 | F21: FALSE | X21: =ISTEXT(Z21) -> TRUE | Z21: {=IF(A21="","", IFERROR( INDEX('혈맹원 정보'!E$2:E1000, MATCH(A21, '혈맹원 정보'!A$2:A1000, 0) ), ""))} -> 1490259813962350592
A22: =IFERROR(__xludf.DUMMYFUNCTION("""COMPUTED_VALUE"""),"세이버") -> 세이버 | B22: FALSE | C22: =IF(Z22="","",COUNTIF('건들지말것'!A:A,Z22)) -> 117 | D22: =C22/$H$1 -> 0.32957746 | E22: =IFERROR(VLOOKUP(TRIM(A22), '혈맹원 정보'!A:C, 3, FALSE), "") -> 요정 | F22: FALSE | X22: =ISTEXT(Z22) -> TRUE | Z22: {=IF(A22="","", IFERROR( INDEX('혈맹원 정보'!E$2:E1000, MATCH(A22, '혈맹원 정보'!A$2:A1000, 0) ), ""))} -> 1278304254955884730
A23: =IFERROR(__xludf.DUMMYFUNCTION("""COMPUTED_VALUE"""),"스타") -> 스타 | B23: FALSE | C23: =IF(Z23="","",COUNTIF('건들지말것'!A:A,Z23)) -> 0 | D23: =C23/$H$1 -> 0 | E23: =IFERROR(VLOOKUP(TRIM(A23), '혈맹원 정보'!A:C, 3, FALSE), "") -> 마법사 | F23: FALSE | X23: =ISTEXT(Z23) -> TRUE | Z23: {=IF(A23="","", IFERROR( INDEX('혈맹원 정보'!E$2:E1000, MATCH(A23, '혈맹원 정보'!A$2:A1000, 0) ), ""))} -> 397696170346151946
A24: =IFERROR(__xludf.DUMMYFUNCTION("""COMPUTED_VALUE"""),"스타1") -> 스타1 | B24: FALSE | C24: =IF(Z24="","",COUNTIF('건들지말것'!A:A,Z24)) -> 147 | D24: =C24/$H$1 -> 0.41408451 | E24: =IFERROR(VLOOKUP(TRIM(A24), '혈맹원 정보'!A:C, 3, FALSE), "") -> 마법사 | F24: FALSE | X24: =ISTEXT(Z25) -> TRUE | Z24: {=IF(A24="","", IFERROR( INDEX('혈맹원 정보'!E$2:E1000, MATCH(A24, '혈맹원 정보'!A$2:A1000, 0) ), ""))} -> 612606740541997066
A25: =IFERROR(__xludf.DUMMYFUNCTION("""COMPUTED_VALUE"""),"스팸라이트") -> 스팸라이트 | B25: FALSE | C25: =IF(Z25="","",COUNTIF('건들지말것'!A:A,Z25)) -> 0 | D25: =C25/$H$1 -> 0 | E25: =IFERROR(VLOOKUP(TRIM(A25), '혈맹원 정보'!A:C, 3, FALSE), "") -> 요정 | F25: FALSE | X25: =ISTEXT(Z26) -> TRUE | Z25: {=IF(A25="","", IFERROR( INDEX('혈맹원 정보'!E$2:E1000, MATCH(A25, '혈맹원 정보'!A$2:A1000, 0) ), ""))} -> 1489588682376613888
A26: =IFERROR(__xludf.DUMMYFUNCTION("""COMPUTED_VALUE"""),"시드랏슈") -> 시드랏슈 | B26: FALSE | C26: =IF(Z26="","",COUNTIF('건들지말것'!A:A,Z26)) -> 92 | D26: =C26/$H$1 -> 0.25915493 | E26: =IFERROR(VLOOKUP(TRIM(A26), '혈맹원 정보'!A:C, 3, FALSE), "") -> 마법사 | F26: FALSE | X26: =ISTEXT(Z27) -> TRUE | Z26: {=IF(A26="","", IFERROR( INDEX('혈맹원 정보'!E$2:E1000, MATCH(A26, '혈맹원 정보'!A$2:A1000, 0) ), ""))} -> 583263839856885770
A27: =IFERROR(__xludf.DUMMYFUNCTION("""COMPUTED_VALUE"""),"시진핑") -> 시진핑 | B27: FALSE | C27: =IF(Z27="","",COUNTIF('건들지말것'!A:A,Z27)) -> 0 | D27: =C27/$H$1 -> 0 | E27: =IFERROR(VLOOKUP(TRIM(A27), '혈맹원 정보'!A:C, 3, FALSE), "") -> 마법사 | F27: FALSE | X27: =ISTEXT(Z27) -> TRUE | Z27: {=IF(A27="","", IFERROR( INDEX('혈맹원 정보'!E$2:E1000, MATCH(A27, '혈맹원 정보'!A$2:A1000, 0) ), ""))} -> 1343575157842640957
A28: =IFERROR(__xludf.DUMMYFUNCTION("""COMPUTED_VALUE"""),"신문") -> 신문 | B28: FALSE | C28: =IF(Z28="","",COUNTIF('건들지말것'!A:A,Z28)) -> 144 | D28: =C28/$H$1 -> 0.4056338 | E28: =IFERROR(VLOOKUP(TRIM(A28), '혈맹원 정보'!A:C, 3, FALSE), "") -> 요정 | F28: FALSE | X28: =ISTEXT(Z28) -> TRUE | Z28: {=IF(A28="","", IFERROR( INDEX('혈맹원 정보'!E$2:E1000, MATCH(A28, '혈맹원 정보'!A$2:A1000, 0) ), ""))} -> 661750424591663134
A29: =IFERROR(__xludf.DUMMYFUNCTION("""COMPUTED_VALUE"""),"쌀떡") -> 쌀떡 | B29: FALSE | C29: =IF(Z29="","",COUNTIF('건들지말것'!A:A,Z29)) -> 30 | D29: =C29/$H$1 -> 0.084507042 | E29: =IFERROR(VLOOKUP(TRIM(A29), '혈맹원 정보'!A:C, 3, FALSE), "") -> 요정 | F29: FALSE | X29: =ISTEXT(Z29) -> TRUE | Z29: {=IF(A29="","", IFERROR( INDEX('혈맹원 정보'!E$2:E1000, MATCH(A29, '혈맹원 정보'!A$2:A1000, 0) ), ""))} -> 1487057737832464544
A30: =IFERROR(__xludf.DUMMYFUNCTION("""COMPUTED_VALUE"""),"쌀떡") -> 쌀떡 | B30: FALSE | C30: =IF(Z30="","",COUNTIF('건들지말것'!A:A,Z30)) -> 30 | D30: =C30/$H$1 -> 0.084507042 | E30: =IFERROR(VLOOKUP(TRIM(A30), '혈맹원 정보'!A:C, 3, FALSE), "") -> 요정 | F30: FALSE | X30: =ISTEXT(Z30) -> TRUE | Z30: {=IF(A30="","", IFERROR( INDEX('혈맹원 정보'!E$2:E1000, MATCH(A30, '혈맹원 정보'!A$2:A1000, 0) ), ""))} -> 1487057737832464544
A31: =IFERROR(__xludf.DUMMYFUNCTION("""COMPUTED_VALUE"""),"썽이") -> 썽이 | B31: FALSE | C31: =IF(Z31="","",COUNTIF('건들지말것'!A:A,Z31)) -> 141 | D31: =C31/$H$1 -> 0.3971831 | E31: =IFERROR(VLOOKUP(TRIM(A31), '혈맹원 정보'!A:C, 3, FALSE), "") -> 요정 | F31: FALSE | X31: =ISTEXT(Z31) -> TRUE | Z31: {=IF(A31="","", IFERROR( INDEX('혈맹원 정보'!E$2:E1000, MATCH(A31, '혈맹원 정보'!A$2:A1000, 0) ), ""))} -> 576257871612870656
A32: =IFERROR(__xludf.DUMMYFUNCTION("""COMPUTED_VALUE"""),"쑥떡") -> 쑥떡 | B32: FALSE | C32: =IF(Z32="","",COUNTIF('건들지말것'!A:A,Z32)) -> 1 | D32: =C32/$H$1 -> 0.0028169014 | E32: =IFERROR(VLOOKUP(TRIM(A32), '혈맹원 정보'!A:C, 3, FALSE), "") -> 요정 | F32: FALSE | X32: =ISTEXT(Z32) -> TRUE | Z32: {=IF(A32="","", IFERROR( INDEX('혈맹원 정보'!E$2:E1000, MATCH(A32, '혈맹원 정보'!A$2:A1000, 0) ), ""))} -> 373116772166926337
A33: =IFERROR(__xludf.DUMMYFUNCTION("""COMPUTED_VALUE"""),"아스테어") -> 아스테어 | B33: FALSE | C33: =IF(Z33="","",COUNTIF('건들지말것'!A:A,Z33)) -> 0 | D33: =C33/$H$1 -> 0 | E33: =IFERROR(VLOOKUP(TRIM(A33), '혈맹원 정보'!A:C, 3, FALSE), "") -> 기사 | F33: FALSE | X33: =ISTEXT(Z33) -> TRUE | Z33: {=IF(A33="","", IFERROR( INDEX('혈맹원 정보'!E$2:E1000, MATCH(A33, '혈맹원 정보'!A$2:A1000, 0) ), ""))} -> 538344294579437598
A34: =IFERROR(__xludf.DUMMYFUNCTION("""COMPUTED_VALUE"""),"악당") -> 악당 | B34: FALSE | C34: =IF(Z34="","",COUNTIF('건들지말것'!A:A,Z34)) -> 93 | D34: =C34/$H$1 -> 0.26197183 | E34: =IFERROR(VLOOKUP(TRIM(A34), '혈맹원 정보'!A:C, 3, FALSE), "") -> 요정 | F34: FALSE | X34: =ISTEXT(Z34) -> TRUE | Z34: {=IF(A34="","", IFERROR( INDEX('혈맹원 정보'!E$2:E1000, MATCH(A34, '혈맹원 정보'!A$2:A1000, 0) ), ""))} -> 366506563957030913
A35: =IFERROR(__xludf.DUMMYFUNCTION("""COMPUTED_VALUE"""),"악당1") -> 악당1 | B35: FALSE | C35: =IF(Z35="","",COUNTIF('건들지말것'!A:A,Z35)) -> 93 | D35: =C35/$H$1 -> 0.26197183 | E35: =IFERROR(VLOOKUP(TRIM(A35), '혈맹원 정보'!A:C, 3, FALSE), "") -> 요정 | F35: FALSE | X35: =ISTEXT(Z35) -> TRUE | Z35: {=IF(A35="","", IFERROR( INDEX('혈맹원 정보'!E$2:E1000, MATCH(A35, '혈맹원 정보'!A$2:A1000, 0) ), ""))} -> 366506563957030913
A36: =IFERROR(__xludf.DUMMYFUNCTION("""COMPUTED_VALUE"""),"어쩐지") -> 어쩐지 | B36: FALSE | C36: =IF(Z36="","",COUNTIF('건들지말것'!A:A,Z36)) -> 15 | D36: =C36/$H$1 -> 0.042253521 | E36: =IFERROR(VLOOKUP(TRIM(A36), '혈맹원 정보'!A:C, 3, FALSE), "") -> 마법사 | F36: FALSE | X36: =ISTEXT(Z36) -> TRUE | Z36: {=IF(A36="","", IFERROR( INDEX('혈맹원 정보'!E$2:E1000, MATCH(A36, '혈맹원 정보'!A$2:A1000, 0) ), ""))} -> 721281407288213544
A37: =IFERROR(__xludf.DUMMYFUNCTION("""COMPUTED_VALUE"""),"얼음여왕") -> 얼음여왕 | B37: FALSE | C37: =IF(Z37="","",COUNTIF('건들지말것'!A:A,Z37)) -> 41 | D37: =C37/$H$1 -> 0.11549296 | E37: =IFERROR(VLOOKUP(TRIM(A37), '혈맹원 정보'!A:C, 3, FALSE), "") -> 요정 | F37: FALSE | X37: =ISTEXT(Z37) -> TRUE | Z37: {=IF(A37="","", IFERROR( INDEX('혈맹원 정보'!E$2:E1000, MATCH(A37, '혈맹원 정보'!A$2:A1000, 0) ), ""))} -> 865842387347046440
A38: =IFERROR(__xludf.DUMMYFUNCTION("""COMPUTED_VALUE"""),"에바") -> 에바 | B38: FALSE | C38: =IF(Z38="","",COUNTIF('건들지말것'!A:A,Z38)) -> 0 | D38: =C38/$H$1 -> 0 | E38: =IFERROR(VLOOKUP(TRIM(A38), '혈맹원 정보'!A:C, 3, FALSE), "") -> 마법사 | F38: FALSE | X38: =ISTEXT(Z38) -> TRUE | Z38: {=IF(A38="","", IFERROR( INDEX('혈맹원 정보'!E$2:E1000, MATCH(A38, '혈맹원 정보'!A$2:A1000, 0) ), ""))} -> 1353407800679596115
A39: =IFERROR(__xludf.DUMMYFUNCTION("""COMPUTED_VALUE"""),"역도") -> 역도 | B39: FALSE | C39: =IF(Z39="","",COUNTIF('건들지말것'!A:A,Z39)) -> 0 | D39: =C39/$H$1 -> 0 | E39: =IFERROR(VLOOKUP(TRIM(A39), '혈맹원 정보'!A:C, 3, FALSE), "") -> 기사 | F39: FALSE | X39: =ISTEXT(Z39) -> TRUE | Z39: {=IF(A39="","", IFERROR( INDEX('혈맹원 정보'!E$2:E1000, MATCH(A39, '혈맹원 정보'!A$2:A1000, 0) ), ""))} -> 346930383591571457
A40: =IFERROR(__xludf.DUMMYFUNCTION("""COMPUTED_VALUE"""),"요요미") -> 요요미 | B40: FALSE | C40: =IF(Z40="","",COUNTIF('건들지말것'!A:A,Z40)) -> 0 | D40: =C40/$H$1 -> 0 | E40: =IFERROR(VLOOKUP(TRIM(A40), '혈맹원 정보'!A:C, 3, FALSE), "") -> 요정 | F40: FALSE | X40: =ISTEXT(Z40) -> TRUE | Z40: {=IF(A40="","", IFERROR( INDEX('혈맹원 정보'!E$2:E1000, MATCH(A40, '혈맹원 정보'!A$2:A1000, 0) ), ""))} -> 553214590926848000
...

Sheet 아이템 분배 순서
A1: 기사 | D1: 요정 | G1: 마법사 | J1: 보는 방법 닉네임/참여율순위
A2: =IFERROR(__xludf.DUMMYFUNCTION("SORT( FILTER({'보탐 참여율'!A:A, '보탐 참여율'!D:D}, '보탐 참여율'!E:E=""기사""), 2, FALSE)"),"개백수") -> 개백수 | B2: =IFERROR(__xludf.DUMMYFUNCTION("""COMPUTED_VALUE"""),0.35492957746478876) -> 0.35492958 | D2: =IFERROR(__xludf.DUMMYFUNCTION("SORT( FILTER({'보탐 참여율'!A:A, '보탐 참여율'!D:D}, '보탐 참여율'!E:E=""요정""), 2, FALSE)"),"하아이") -> 하아이 | E2: =IFERROR(__xludf.DUMMYFUNCTION("""COMPUTED_VALUE"""),0.5577464788732395) -> 0.55774648 | G2: =IFERROR(__xludf.DUMMYFUNCTION("SORT( FILTER({'보탐 참여율'!A:A, '보탐 참여율'!D:D}, '보탐 참여율'!E:E=""마법사""), 2, FALSE)"),"스타1") -> 스타1 | H2: =IFERROR(__xludf.DUMMYFUNCTION("""COMPUTED_VALUE"""),0.4140845070422535) -> 0.41408451
A3: =IFERROR(__xludf.DUMMYFUNCTION("""COMPUTED_VALUE"""),"드레이크1") -> 드레이크1 | B3: =IFERROR(__xludf.DUMMYFUNCTION("""COMPUTED_VALUE"""),0.30985915492957744) -> 0.30985915 | D3: =IFERROR(__xludf.DUMMYFUNCTION("""COMPUTED_VALUE"""),"최선미") -> 최선미 | E3: =IFERROR(__xludf.DUMMYFUNCTION("""COMPUTED_VALUE"""),0.5352112676056338) -> 0.53521127 | G3: =IFERROR(__xludf.DUMMYFUNCTION("""COMPUTED_VALUE"""),"유니세프") -> 유니세프 | H3: =IFERROR(__xludf.DUMMYFUNCTION("""COMPUTED_VALUE"""),0.2647887323943662) -> 0.26478873
A4: =IFERROR(__xludf.DUMMYFUNCTION("""COMPUTED_VALUE"""),"자자") -> 자자 | B4: =IFERROR(__xludf.DUMMYFUNCTION("""COMPUTED_VALUE"""),0.22253521126760564) -> 0.22253521 | D4: =IFERROR(__xludf.DUMMYFUNCTION("""COMPUTED_VALUE"""),"ECO") -> ECO | E4: =IFERROR(__xludf.DUMMYFUNCTION("""COMPUTED_VALUE"""),0.5154929577464789) -> 0.51549296 | G4: =IFERROR(__xludf.DUMMYFUNCTION("""COMPUTED_VALUE"""),"시드랏슈") -> 시드랏슈 | H4: =IFERROR(__xludf.DUMMYFUNCTION("""COMPUTED_VALUE"""),0.2591549295774648) -> 0.25915493
A5: =IFERROR(__xludf.DUMMYFUNCTION("""COMPUTED_VALUE"""),"비에고") -> 비에고 | B5: =IFERROR(__xludf.DUMMYFUNCTION("""COMPUTED_VALUE"""),0.11830985915492957) -> 0.11830986 | D5: =IFERROR(__xludf.DUMMYFUNCTION("""COMPUTED_VALUE"""),"OSAKA") -> OSAKA | E5: =IFERROR(__xludf.DUMMYFUNCTION("""COMPUTED_VALUE"""),0.48732394366197185) -> 0.48732394 | G5: =IFERROR(__xludf.DUMMYFUNCTION("""COMPUTED_VALUE"""),"김현지") -> 김현지 | H5: =IFERROR(__xludf.DUMMYFUNCTION("""COMPUTED_VALUE"""),0.22253521126760564) -> 0.22253521
A6: =IFERROR(__xludf.DUMMYFUNCTION("""COMPUTED_VALUE"""),"덱스") -> 덱스 | B6: =IFERROR(__xludf.DUMMYFUNCTION("""COMPUTED_VALUE"""),0.10704225352112676) -> 0.10704225 | D6: =IFERROR(__xludf.DUMMYFUNCTION("""COMPUTED_VALUE"""),"주짱") -> 주짱 | E6: =IFERROR(__xludf.DUMMYFUNCTION("""COMPUTED_VALUE"""),0.4732394366197183) -> 0.47323944 | G6: =IFERROR(__xludf.DUMMYFUNCTION("""COMPUTED_VALUE"""),"두둥탁") -> 두둥탁 | H6: =IFERROR(__xludf.DUMMYFUNCTION("""COMPUTED_VALUE"""),0.14929577464788732) -> 0.14929577
A7: =IFERROR(__xludf.DUMMYFUNCTION("""COMPUTED_VALUE"""),"꽃냥") -> 꽃냥 | B7: =IFERROR(__xludf.DUMMYFUNCTION("""COMPUTED_VALUE"""),0.09577464788732394) -> 0.095774648 | D7: =IFERROR(__xludf.DUMMYFUNCTION("""COMPUTED_VALUE"""),"대곡주") -> 대곡주 | E7: =IFERROR(__xludf.DUMMYFUNCTION("""COMPUTED_VALUE"""),0.4450704225352113) -> 0.44507042 | G7: =IFERROR(__xludf.DUMMYFUNCTION("""COMPUTED_VALUE"""),"뱀") -> 뱀 | H7: =IFERROR(__xludf.DUMMYFUNCTION("""COMPUTED_VALUE"""),0.04788732394366197) -> 0.047887324
A8: =IFERROR(__xludf.DUMMYFUNCTION("""COMPUTED_VALUE"""),"드레이크") -> 드레이크 | B8: =IFERROR(__xludf.DUMMYFUNCTION("""COMPUTED_VALUE"""),0.03943661971830986) -> 0.03943662 | D8: =IFERROR(__xludf.DUMMYFUNCTION("""COMPUTED_VALUE"""),"신문") -> 신문 | E8: =IFERROR(__xludf.DUMMYFUNCTION("""COMPUTED_VALUE"""),0.4056338028169014) -> 0.4056338 | G8: =IFERROR(__xludf.DUMMYFUNCTION("""COMPUTED_VALUE"""),"어쩐지") -> 어쩐지 | H8: =IFERROR(__xludf.DUMMYFUNCTION("""COMPUTED_VALUE"""),0.04225352112676056) -> 0.042253521
A9: =IFERROR(__xludf.DUMMYFUNCTION("""COMPUTED_VALUE"""),"최민우") -> 최민우 | B9: =IFERROR(__xludf.DUMMYFUNCTION("""COMPUTED_VALUE"""),0.030985915492957747) -> 0.030985915 | D9: =IFERROR(__xludf.DUMMYFUNCTION("""COMPUTED_VALUE"""),"썽이") -> 썽이 | E9: =IFERROR(__xludf.DUMMYFUNCTION("""COMPUTED_VALUE"""),0.3971830985915493) -> 0.3971831 | G9: =IFERROR(__xludf.DUMMYFUNCTION("""COMPUTED_VALUE"""),"스타") -> 스타 | H9: =IFERROR(__xludf.DUMMYFUNCTION("""COMPUTED_VALUE"""),0.0) -> 0
A10: =IFERROR(__xludf.DUMMYFUNCTION("""COMPUTED_VALUE"""),"아스테어") -> 아스테어 | B10: =IFERROR(__xludf.DUMMYFUNCTION("""COMPUTED_VALUE"""),0.0) -> 0 | D10: =IFERROR(__xludf.DUMMYFUNCTION("""COMPUTED_VALUE"""),"팽자") -> 팽자 | E10: =IFERROR(__xludf.DUMMYFUNCTION("""COMPUTED_VALUE"""),0.37746478873239436) -> 0.37746479 | G10: =IFERROR(__xludf.DUMMYFUNCTION("""COMPUTED_VALUE"""),"시진핑") -> 시진핑 | H10: =IFERROR(__xludf.DUMMYFUNCTION("""COMPUTED_VALUE"""),0.0) -> 0
A11: =IFERROR(__xludf.DUMMYFUNCTION("""COMPUTED_VALUE"""),"역도") -> 역도 | B11: =IFERROR(__xludf.DUMMYFUNCTION("""COMPUTED_VALUE"""),0.0) -> 0 | D11: =IFERROR(__xludf.DUMMYFUNCTION("""COMPUTED_VALUE"""),"레오나르도") -> 레오나르도 | E11: =IFERROR(__xludf.DUMMYFUNCTION("""COMPUTED_VALUE"""),0.3323943661971831) -> 0.33239437 | G11: =IFERROR(__xludf.DUMMYFUNCTION("""COMPUTED_VALUE"""),"에바") -> 에바 | H11: =IFERROR(__xludf.DUMMYFUNCTION("""COMPUTED_VALUE"""),0.0) -> 0
A12: =IFERROR(__xludf.DUMMYFUNCTION("""COMPUTED_VALUE"""),"이중") -> 이중 | B12: =IFERROR(__xludf.DUMMYFUNCTION("""COMPUTED_VALUE"""),0.0) -> 0 | D12: =IFERROR(__xludf.DUMMYFUNCTION("""COMPUTED_VALUE"""),"세이버") -> 세이버 | E12: =IFERROR(__xludf.DUMMYFUNCTION("""COMPUTED_VALUE"""),0.3295774647887324) -> 0.32957746 | G12: =IFERROR(__xludf.DUMMYFUNCTION("""COMPUTED_VALUE"""),"잭스") -> 잭스 | H12: =IFERROR(__xludf.DUMMYFUNCTION("""COMPUTED_VALUE"""),0.0) -> 0
D13: =IFERROR(__xludf.DUMMYFUNCTION("""COMPUTED_VALUE"""),"두끗") -> 두끗 | E13: =IFERROR(__xludf.DUMMYFUNCTION("""COMPUTED_VALUE"""),0.28169014084507044) -> 0.28169014 | G13: =IFERROR(__xludf.DUMMYFUNCTION("""COMPUTED_VALUE"""),"전생") -> 전생 | H13: =IFERROR(__xludf.DUMMYFUNCTION("""COMPUTED_VALUE"""),0.0) -> 0
D14: =IFERROR(__xludf.DUMMYFUNCTION("""COMPUTED_VALUE"""),"밀떡") -> 밀떡 | E14: =IFERROR(__xludf.DUMMYFUNCTION("""COMPUTED_VALUE"""),0.27605633802816903) -> 0.27605634 | G14: =IFERROR(__xludf.DUMMYFUNCTION("""COMPUTED_VALUE"""),"턳") -> 턳 | H14: =IFERROR(__xludf.DUMMYFUNCTION("""COMPUTED_VALUE"""),0.0) -> 0
D15: =IFERROR(__xludf.DUMMYFUNCTION("""COMPUTED_VALUE"""),"악당") -> 악당 | E15: =IFERROR(__xludf.DUMMYFUNCTION("""COMPUTED_VALUE"""),0.2619718309859155) -> 0.26197183
D16: =IFERROR(__xludf.DUMMYFUNCTION("""COMPUTED_VALUE"""),"악당1") -> 악당1 | E16: =IFERROR(__xludf.DUMMYFUNCTION("""COMPUTED_VALUE"""),0.2619718309859155) -> 0.26197183
D17: =IFERROR(__xludf.DUMMYFUNCTION("""COMPUTED_VALUE"""),"쥬드") -> 쥬드 | E17: =IFERROR(__xludf.DUMMYFUNCTION("""COMPUTED_VALUE"""),0.2591549295774648) -> 0.25915493
D18: =IFERROR(__xludf.DUMMYFUNCTION("""COMPUTED_VALUE"""),"세끗") -> 세끗 | E18: =IFERROR(__xludf.DUMMYFUNCTION("""COMPUTED_VALUE"""),0.23380281690140844) -> 0.23380282
D19: =IFERROR(__xludf.DUMMYFUNCTION("""COMPUTED_VALUE"""),"민창") -> 민창 | E19: =IFERROR(__xludf.DUMMYFUNCTION("""COMPUTED_VALUE"""),0.22535211267605634) -> 0.22535211
D20: =IFERROR(__xludf.DUMMYFUNCTION("""COMPUTED_VALUE"""),"한끗") -> 한끗 | E20: =IFERROR(__xludf.DUMMYFUNCTION("""COMPUTED_VALUE"""),0.22253521126760564) -> 0.22253521
D21: =IFERROR(__xludf.DUMMYFUNCTION("""COMPUTED_VALUE"""),"닥스") -> 닥스 | E21: =IFERROR(__xludf.DUMMYFUNCTION("""COMPUTED_VALUE"""),0.2140845070422535) -> 0.21408451
D22: =IFERROR(__xludf.DUMMYFUNCTION("""COMPUTED_VALUE"""),"화장실") -> 화장실 | E22: =IFERROR(__xludf.DUMMYFUNCTION("""COMPUTED_VALUE"""),0.18591549295774648) -> 0.18591549
D23: =IFERROR(__xludf.DUMMYFUNCTION("""COMPUTED_VALUE"""),"당구장") -> 당구장 | E23: =IFERROR(__xludf.DUMMYFUNCTION("""COMPUTED_VALUE"""),0.16619718309859155) -> 0.16619718
D24: =IFERROR(__xludf.DUMMYFUNCTION("""COMPUTED_VALUE"""),"또가스") -> 또가스 | E24: =IFERROR(__xludf.DUMMYFUNCTION("""COMPUTED_VALUE"""),0.16338028169014085) -> 0.16338028
D25: =IFERROR(__xludf.DUMMYFUNCTION("""COMPUTED_VALUE"""),"얼음여왕") -> 얼음여왕 | E25: =IFERROR(__xludf.DUMMYFUNCTION("""COMPUTED_VALUE"""),0.11549295774647887) -> 0.11549296
D26: =IFERROR(__xludf.DUMMYFUNCTION("""COMPUTED_VALUE"""),"쌀떡") -> 쌀떡 | E26: =IFERROR(__xludf.DUMMYFUNCTION("""COMPUTED_VALUE"""),0.08450704225352113) -> 0.084507042
D27: =IFERROR(__xludf.DUMMYFUNCTION("""COMPUTED_VALUE"""),"쌀떡") -> 쌀떡 | E27: =IFERROR(__xludf.DUMMYFUNCTION("""COMPUTED_VALUE"""),0.08450704225352113) -> 0.084507042
D28: =IFERROR(__xludf.DUMMYFUNCTION("""COMPUTED_VALUE"""),"다뢰") -> 다뢰 | E28: =IFERROR(__xludf.DUMMYFUNCTION("""COMPUTED_VALUE"""),0.07323943661971831) -> 0.073239437
D29: =IFERROR(__xludf.DUMMYFUNCTION("""COMPUTED_VALUE"""),"새롬") -> 새롬 | E29: =IFERROR(__xludf.DUMMYFUNCTION("""COMPUTED_VALUE"""),0.07323943661971831) -> 0.073239437
D30: =IFERROR(__xludf.DUMMYFUNCTION("""COMPUTED_VALUE"""),"윤짱") -> 윤짱 | E30: =IFERROR(__xludf.DUMMYFUNCTION("""COMPUTED_VALUE"""),0.04225352112676056) -> 0.042253521
D31: =IFERROR(__xludf.DUMMYFUNCTION("""COMPUTED_VALUE"""),"자자1") -> 자자1 | E31: =IFERROR(__xludf.DUMMYFUNCTION("""COMPUTED_VALUE"""),0.028169014084507043) -> 0.028169014
D32: =IFERROR(__xludf.DUMMYFUNCTION("""COMPUTED_VALUE"""),"해하") -> 해하 | E32: =IFERROR(__xludf.DUMMYFUNCTION("""COMPUTED_VALUE"""),0.022535211267605635) -> 0.022535211
D33: =IFERROR(__xludf.DUMMYFUNCTION("""COMPUTED_VALUE"""),"졋탱") -> 졋탱 | E33: =IFERROR(__xludf.DUMMYFUNCTION("""COMPUTED_VALUE"""),0.008450704225352112) -> 0.0084507042
D34: =IFERROR(__xludf.DUMMYFUNCTION("""COMPUTED_VALUE"""),"복식") -> 복식 | E34: =IFERROR(__xludf.DUMMYFUNCTION("""COMPUTED_VALUE"""),0.0028169014084507044) -> 0.0028169014
D35: =IFERROR(__xludf.DUMMYFUNCTION("""COMPUTED_VALUE"""),"쑥떡") -> 쑥떡 | E35: =IFERROR(__xludf.DUMMYFUNCTION("""COMPUTED_VALUE"""),0.0028169014084507044) -> 0.0028169014
D36: =IFERROR(__xludf.DUMMYFUNCTION("""COMPUTED_VALUE"""),"스팸라이트") -> 스팸라이트 | E36: =IFERROR(__xludf.DUMMYFUNCTION("""COMPUTED_VALUE"""),0.0) -> 0
D37: =IFERROR(__xludf.DUMMYFUNCTION("""COMPUTED_VALUE"""),"요요미") -> 요요미 | E37: =IFERROR(__xludf.DUMMYFUNCTION("""COMPUTED_VALUE"""),0.0) -> 0
D38: =IFERROR(__xludf.DUMMYFUNCTION("""COMPUTED_VALUE"""),"육떡") -> 육떡 | E38: =IFERROR(__xludf.DUMMYFUNCTION("""COMPUTED_VALUE"""),0.0) -> 0
D39: =IFERROR(__xludf.DUMMYFUNCTION("""COMPUTED_VALUE"""),"파아그리오") -> 파아그리오 | E39: =IFERROR(__xludf.DUMMYFUNCTION("""COMPUTED_VALUE"""),0.0) -> 0

Sheet 건들지말것
A1: 310008488245985292
A2: 312126990935130124
A3: 322353660938158081
A4: 376298390822060034
A5: 561208372171505683
A6: 612606740541997066
A7: 661750424591663134
A8: 759374340306632705
A9: 939455236739837982
A10: 1020371875743924264
A11: 1053683139056255027
A12: 1261275854508396708
... A3765: 1278304254955884730

Sheet 월별 보탐참여율
A1: 월별 보탐 참여율 순위 | D1: 46113
A2: 기사 | B2: 마법사 | C2: 요정 | D2: 순위
A3: =IFERROR(__xludf.DUMMYFUNCTION("IFERROR(INDEX(FILTER($W:$W,$T:$T=$D$1,$U:$U=""기사"",$V:$V=ROW()-2),1),"""")"),"비에고") -> 비에고 | B3: =IFERROR(__xludf.DUMMYFUNCTION("IFERROR(INDEX(FILTER($W:$W,$T:$T=$D$1,$U:$U=""마법사"",$V:$V=ROW()-2),1),"""")"),"스타") -> 스타 | C3: =IFERROR(__xludf.DUMMYFUNCTION("IFERROR(INDEX(FILTER($W:$W,$T:$T=$D$1,$U:$U=""요정"",$V:$V=ROW()-2),1),"""")"),"파도") -> 파도 | D3: 1위
A4: =IFERROR(__xludf.DUMMYFUNCTION("IFERROR(INDEX(FILTER($W:$W,$T:$T=$D$1,$U:$U=""기사"",$V:$V=ROW()-2),1),"""")"),"대위덕명왕") -> 대위덕명왕 | B4: =IFERROR(__xludf.DUMMYFUNCTION("IFERROR(INDEX(FILTER($W:$W,$T:$T=$D$1,$U:$U=""마법사"",$V:$V=ROW()-2),1),"""")"),"턳") -> 턳 | C4: =IFERROR(__xludf.DUMMYFUNCTION("IFERROR(INDEX(FILTER($W:$W,$T:$T=$D$1,$U:$U=""요정"",$V:$V=ROW()-2),1),"""")"),"복식") -> 복식 | D4: 2위
A5: =IFERROR(__xludf.DUMMYFUNCTION("IFERROR(INDEX(FILTER($W:$W,$T:$T=$D$1,$U:$U=""기사"",$V:$V=ROW()-2),1),"""")"),"수") -> 수 | B5: =IFERROR(__xludf.DUMMYFUNCTION("IFERROR(INDEX(FILTER($W:$W,$T:$T=$D$1,$U:$U=""마법사"",$V:$V=ROW()-2),1),"""")"),"시드랏슈") -> 시드랏슈 | C5: =IFERROR(__xludf.DUMMYFUNCTION("IFERROR(INDEX(FILTER($W:$W,$T:$T=$D$1,$U:$U=""요정"",$V:$V=ROW()-2),1),"""")"),"OSAKA") -> OSAKA | D5: 3위
A6: =IFERROR(__xludf.DUMMYFUNCTION("IFERROR(INDEX(FILTER($W:$W,$T:$T=$D$1,$U:$U=""기사"",$V:$V=ROW()-2),1),"""")"),"듀크데필") -> 듀크데필 | B6: =IFERROR(__xludf.DUMMYFUNCTION("IFERROR(INDEX(FILTER($W:$W,$T:$T=$D$1,$U:$U=""마법사"",$V:$V=ROW()-2),1),"""")"),"전생") -> 전생 | C6: =IFERROR(__xludf.DUMMYFUNCTION("IFERROR(INDEX(FILTER($W:$W,$T:$T=$D$1,$U:$U=""요정"",$V:$V=ROW()-2),1),"""")"),"신문") -> 신문 | D6: 4위
A7: =IFERROR(__xludf.DUMMYFUNCTION("IFERROR(INDEX(FILTER($W:$W,$T:$T=$D$1,$U:$U=""기사"",$V:$V=ROW()-2),1),"""")"),"이중") -> 이중 | B7: =IFERROR(__xludf.DUMMYFUNCTION("IFERROR(INDEX(FILTER($W:$W,$T:$T=$D$1,$U:$U=""마법사"",$V:$V=ROW()-2),1),"""")"),"두둥탁") -> 두둥탁 | C7: =IFERROR(__xludf.DUMMYFUNCTION("IFERROR(INDEX(FILTER($W:$W,$T:$T=$D$1,$U:$U=""요정"",$V:$V=ROW()-2),1),"""")"),"대곡주") -> 대곡주 | D7: 5위
A8: =IFERROR(__xludf.DUMMYFUNCTION("IFERROR(INDEX(FILTER($W:$W,$T:$T=$D$1,$U:$U=""기사"",$V:$V=ROW()-2),1),"""")"),"자자") -> 자자 | B8: =IFERROR(__xludf.DUMMYFUNCTION("IFERROR(INDEX(FILTER($W:$W,$T:$T=$D$1,$U:$U=""마법사"",$V:$V=ROW()-2),1),"""")"),"흑마술사") -> 흑마술사 | C8: =IFERROR(__xludf.DUMMYFUNCTION("IFERROR(INDEX(FILTER($W:$W,$T:$T=$D$1,$U:$U=""요정"",$V:$V=ROW()-2),1),"""")"),"요요미") -> 요요미 | D8: 6위
A9: =IFERROR(__xludf.DUMMYFUNCTION("IFERROR(INDEX(FILTER($W:$W,$T:$T=$D$1,$U:$U=""기사"",$V:$V=ROW()-2),1),"""")"),"르비") -> 르비 | B9: =IFERROR(__xludf.DUMMYFUNCTION("IFERROR(INDEX(FILTER($W:$W,$T:$T=$D$1,$U:$U=""마법사"",$V:$V=ROW()-2),1),"""")"),"교랑") -> 교랑 | C9: =IFERROR(__xludf.DUMMYFUNCTION("IFERROR(INDEX(FILTER($W:$W,$T:$T=$D$1,$U:$U=""요정"",$V:$V=ROW()-2),1),"""")"),"하아이") -> 하아이 | D9: 7위
A10: =IFERROR(__xludf.DUMMYFUNCTION("IFERROR(INDEX(FILTER($W:$W,$T:$T=$D$1,$U:$U=""기사"",$V:$V=ROW()-2),1),"""")"),"문다") -> 문다 | B10: =IFERROR(__xludf.DUMMYFUNCTION("IFERROR(INDEX(FILTER($W:$W,$T:$T=$D$1,$U:$U=""마법사"",$V:$V=ROW()-2),1),"""")"),"윤겔라") -> 윤겔라 | C10: =IFERROR(__xludf.DUMMYFUNCTION("IFERROR(INDEX(FILTER($W:$W,$T:$T=$D$1,$U:$U=""요정"",$V:$V=ROW()-2),1),"""")"),"주짱") -> 주짱 | D10: 8위
A11: =IFERROR(__xludf.DUMMYFUNCTION("IFERROR(INDEX(FILTER($W:$W,$T:$T=$D$1,$U:$U=""기사"",$V:$V=ROW()-2),1),"""")"),"저팔게") -> 저팔게 | B11: =IFERROR(__xludf.DUMMYFUNCTION("IFERROR(INDEX(FILTER($W:$W,$T:$T=$D$1,$U:$U=""마법사"",$V:$V=ROW()-2),1),"""")"),"어쩐지") -> 어쩐지 | C11: =IFERROR(__xludf.DUMMYFUNCTION("IFERROR(INDEX(FILTER($W:$W,$T:$T=$D$1,$U:$U=""요정"",$V:$V=ROW()-2),1),"""")"),"쓰레빠") -> 쓰레빠 | D11: 9위
A12: =IFERROR(__xludf.DUMMYFUNCTION("IFERROR(INDEX(FILTER($W:$W,$T:$T=$D$1,$U:$U=""기사"",$V:$V=ROW()-2),1),"""")"),"내가군터") -> 내가군터 | B12: =IFERROR(__xludf.DUMMYFUNCTION("IFERROR(INDEX(FILTER($W:$W,$T:$T=$D$1,$U:$U=""마법사"",$V:$V=ROW()-2),1),"""")"),"에바") -> 에바 | C12: =IFERROR(__xludf.DUMMYFUNCTION("IFERROR(INDEX(FILTER($W:$W,$T:$T=$D$1,$U:$U=""요정"",$V:$V=ROW()-2),1),"""")"),"ECO") -> ECO | D12: 10위
T13: 46113 | U13: 마법사 | V13: 1 | W13: 스타
T14: 46113 | U14: 마법사 | V14: 2 | W14: 턳
T15: 46113 | U15: 마법사 | V15: 3 | W15: 시드랏슈
T16: 46113 | U16: 마법사 | V16: 4 | W16: 전생
T17: 46113 | U17: 마법사 | V17: 5 | W17: 두둥탁
T18: 46113 | U18: 마법사 | V18: 6 | W18: 흑마술사
T19: 46113 | U19: 마법사 | V19: 7 | W19: 교랑
T20: 46113 | U20: 마법사 | V20: 8 | W20: 윤겔라
T21: 46113 | U21: 마법사 | V21: 9 | W21: 어쩐지
T22: 46113 | U22: 마법사 | V22: 10 | W22: 에바
T23: 46113 | U23: 요정 | V23: 1 | W23: 파도
T24: 46113 | U24: 요정 | V24: 2 | W24: 복식
... T105: 46113 | U105: 군주 | V105: 1 | W105: 포카칩

Sheet 애로사항
